<robot name = "robot">
    <link name="Torso">
        <inertial>
            <origin xyz="0 -10 1.4090852278780965" rpy="0 0 0"/>
            <mass value="1" />
            <inertia ixx="100" ixy="0" ixz="0" iyy="100" iyz="0" izz="100" />
        </inertial>
        <visual>
            <origin xyz="0 -10 1.4090852278780965" rpy="0 0 0"/>
            <geometry>
                <box size="1 1 1" />
            </geometry>
            <material name="Cyan">
                <color rgba="0 1.0 1.0 1.0"/>
            </material>
        </visual>
        <collision>
            <origin xyz="0 -10 1.4090852278780965" rpy="0 0 0"/>
            <geometry>
                <box size="1 1 1" />
            </geometry>
        </collision>
    </link>
    <joint name="Torso_BackLeg" type="revolute">
       <parent link="Torso"/>
       <child  link="BackLeg"/>
       <origin rpy="0 0 0" xyz="0 -10.5 1.4090852278780965" />
     <axis xyz="1 0 0"/>
       <limit effort="0.0" lower="-3.14159" upper="3.14159" velocity="0.0"/>
    </joint>
    <link name="BackLeg">
        <inertial>
            <origin xyz="0 -0.7045426139390483 0" rpy="0 0 0"/>
            <mass value="1" />
            <inertia ixx="100" ixy="0" ixz="0" iyy="100" iyz="0" izz="100" />
        </inertial>
        <visual>
            <origin xyz="0 -0.7045426139390483 0" rpy="0 0 0"/>
            <geometry>
                <box size="0.2 1.4090852278780965 0.2" />
            </geometry>
            <material name="Cyan">
                <color rgba="0 1.0 1.0 1.0"/>
            </material>
        </visual>
        <collision>
            <origin xyz="0 -0.7045426139390483 0" rpy="0 0 0"/>
            <geometry>
                <box size="0.2 1.4090852278780965 0.2" />
            </geometry>
        </collision>
    </link>
    <joint name="Torso_FrontLeg" type="revolute">
       <parent link="Torso"/>
       <child  link="FrontLeg"/>
       <origin rpy="0 0 0" xyz="0 -9.5 1.4090852278780965" />
     <axis xyz="1 0 0"/>
       <limit effort="0.0" lower="-3.14159" upper="3.14159" velocity="0.0"/>
    </joint>
    <link name="FrontLeg">
        <inertial>
            <origin xyz="0 0.4803947437130627 0" rpy="0 0 0"/>
            <mass value="1" />
            <inertia ixx="100" ixy="0" ixz="0" iyy="100" iyz="0" izz="100" />
        </inertial>
        <visual>
            <origin xyz="0 0.4803947437130627 0" rpy="0 0 0"/>
            <geometry>
                <box size="0.2 0.9607894874261254 0.2" />
            </geometry>
            <material name="Cyan">
                <color rgba="0 1.0 1.0 1.0"/>
            </material>
        </visual>
        <collision>
            <origin xyz="0 0.4803947437130627 0" rpy="0 0 0"/>
            <geometry>
                <box size="0.2 0.9607894874261254 0.2" />
            </geometry>
        </collision>
    </link>
    <joint name="Torso_LeftLeg" type="revolute">
       <parent link="Torso"/>
       <child  link="LeftLeg"/>
       <origin rpy="0 0 0" xyz="-0.5 -10 1.4090852278780965" />
     <axis xyz="0 1 0"/>
       <limit effort="0.0" lower="-3.14159" upper="3.14159" velocity="0.0"/>
    </joint>
    <link name="LeftLeg">
        <inertial>
            <origin xyz="-0.5232015137424066 0 0" rpy="0 0 0"/>
            <mass value="1" />
            <inertia ixx="100" ixy="0" ixz="0" iyy="100" iyz="0" izz="100" />
        </inertial>
        <visual>
            <origin xyz="-0.5232015137424066 0 0" rpy="0 0 0"/>
            <geometry>
                <box size="1.0464030274848133 0.2 0.2" />
            </geometry>
            <material name="Cyan">
                <color rgba="0 1.0 1.0 1.0"/>
            </material>
        </visual>
        <collision>
            <origin xyz="-0.5232015137424066 0 0" rpy="0 0 0"/>
            <geometry>
                <box size="1.0464030274848133 0.2 0.2" />
            </geometry>
        </collision>
    </link>
    <joint name="Torso_RightLeg" type="revolute">
       <parent link="Torso"/>
       <child  link="RightLeg"/>
       <origin rpy="0 0 0" xyz="0.5 -10 1.4090852278780965" />
     <axis xyz="0 1 0"/>
       <limit effort="0.0" lower="-3.14159" upper="3.14159" velocity="0.0"/>
    </joint>
    <link name="RightLeg">
        <inertial>
            <origin xyz="0.6570869811298627 0 0" rpy="0 0 0"/>
            <mass value="1" />
            <inertia ixx="100" ixy="0" ixz="0" iyy="100" iyz="0" izz="100" />
        </inertial>
        <visual>
            <origin xyz="0.6570869811298627 0 0" rpy="0 0 0"/>
            <geometry>
                <box size="1.3141739622597255 0.2 0.2" />
            </geometry>
            <material name="Cyan">
                <color rgba="0 1.0 1.0 1.0"/>
            </material>
        </visual>
        <collision>
            <origin xyz="0.6570869811298627 0 0" rpy="0 0 0"/>
            <geometry>
                <box size="1.3141739622597255 0.2 0.2" />
            </geometry>
        </collision>
    </link>
    <joint name="BackLeg_BackLowerLeg" type="revolute">
       <parent link="BackLeg"/>
       <child  link="BackLowerLeg"/>
       <origin rpy="0 0 0" xyz="0 -1.4090852278780965 0" />
     <axis xyz="1 0 0"/>
       <limit effort="0.0" lower="-3.14159" upper="3.14159" velocity="0.0"/>
    </joint>
    <link name="BackLowerLeg">
        <inertial>
            <origin xyz="0 0 -0.28388208512319435" rpy="0 0 0"/>
            <mass value="1" />
            <inertia ixx="100" ixy="0" ixz="0" iyy="100" iyz="0" izz="100" />
        </inertial>
        <visual>
            <origin xyz="0 0 -0.28388208512319435" rpy="0 0 0"/>
            <geometry>
                <box size="0.2 0.2 0.5677641702463887" />
            </geometry>
            <material name="Cyan">
                <color rgba="0 1.0 1.0 1.0"/>
            </material>
        </visual>
        <collision>
            <origin xyz="0 0 -0.28388208512319435" rpy="0 0 0"/>
            <geometry>
                <box size="0.2 0.2 0.5677641702463887" />
            </geometry>
        </collision>
    </link>
    <joint name="FrontLeg_FrontLowerLeg" type="revolute">
       <parent link="FrontLeg"/>
       <child  link="FrontLowerLeg"/>
       <origin rpy="0 0 0" xyz="0 0.9607894874261254 0" />
     <axis xyz="1 0 0"/>
       <limit effort="0.0" lower="-3.14159" upper="3.14159" velocity="0.0"/>
    </joint>
    <link name="FrontLowerLeg">
        <inertial>
            <origin xyz="0 0 -0.5468525309005514" rpy="0 0 0"/>
            <mass value="1" />
            <inertia ixx="100" ixy="0" ixz="0" iyy="100" iyz="0" izz="100" />
        </inertial>
        <visual>
            <origin xyz="0 0 -0.5468525309005514" rpy="0 0 0"/>
            <geometry>
                <box size="0.2 0.2 1.0937050618011028" />
            </geometry>
            <material name="Cyan">
                <color rgba="0 1.0 1.0 1.0"/>
            </material>
        </visual>
        <collision>
            <origin xyz="0 0 -0.5468525309005514" rpy="0 0 0"/>
            <geometry>
                <box size="0.2 0.2 1.0937050618011028" />
            </geometry>
        </collision>
    </link>
    <joint name="LeftLeg_LeftLowerLeg" type="revolute">
       <parent link="LeftLeg"/>
       <child  link="LeftLowerLeg"/>
       <origin rpy="0 0 0" xyz="-1.0464030274848133 0 0" />
     <axis xyz="0 1 0"/>
       <limit effort="0.0" lower="-3.14159" upper="3.14159" velocity="0.0"/>
    </joint>
    <link name="LeftLowerLeg">
        <inertial>
            <origin xyz="0 0 -0.6737869111462254" rpy="0 0 0"/>
            <mass value="1" />
            <inertia ixx="100" ixy="0" ixz="0" iyy="100" iyz="0" izz="100" />
        </inertial>
        <visual>
            <origin xyz="0 0 -0.6737869111462254" rpy="0 0 0"/>
            <geometry>
                <box size="0.2 0.2 1.3475738222924507" />
            </geometry>
            <material name="Cyan">
                <color rgba="0 1.0 1.0 1.0"/>
            </material>
        </visual>
        <collision>
            <origin xyz="0 0 -0.6737869111462254" rpy="0 0 0"/>
            <geometry>
                <box size="0.2 0.2 1.3475738222924507" />
            </geometry>
        </collision>
    </link>
    <joint name="RightLeg_RightLowerLeg" type="revolute">
       <parent link="RightLeg"/>
       <child  link="RightLowerLeg"/>
       <origin rpy="0 0 0" xyz="1.3141739622597255 0 0" />
     <axis xyz="0 1 0"/>
       <limit effort="0.0" lower="-3.14159" upper="3.14159" velocity="0.0"/>
    </joint>
    <link name="RightLowerLeg">
        <inertial>
            <origin xyz="0 0 -0.4755437808723779" rpy="0 0 0"/>
            <mass value="1" />
            <inertia ixx="100" ixy="0" ixz="0" iyy="100" iyz="0" izz="100" />
        </inertial>
        <visual>
            <origin xyz="0 0 -0.4755437808723779" rpy="0 0 0"/>
            <geometry>
                <box size="0.2 0.2 0.9510875617447558" />
            </geometry>
            <material name="Cyan">
                <color rgba="0 1.0 1.0 1.0"/>
            </material>
        </visual>
        <collision>
            <origin xyz="0 0 -0.4755437808723779" rpy="0 0 0"/>
            <geometry>
                <box size="0.2 0.2 0.9510875617447558" />
            </geometry>
        </collision>
    </link>
</robot>