<robot name = "robot">
    <link name="Torso">
        <inertial>
            <origin xyz="0 -10 1.4784289620996685" rpy="0 0 0"/>
            <mass value="1" />
            <inertia ixx="100" ixy="0" ixz="0" iyy="100" iyz="0" izz="100" />
        </inertial>
        <visual>
            <origin xyz="0 -10 1.4784289620996685" rpy="0 0 0"/>
            <geometry>
                <box size="1 1 1" />
            </geometry>
            <material name="Cyan">
                <color rgba="0 1.0 1.0 1.0"/>
            </material>
        </visual>
        <collision>
            <origin xyz="0 -10 1.4784289620996685" rpy="0 0 0"/>
            <geometry>
                <box size="1 1 1" />
            </geometry>
        </collision>
    </link>
    <joint name="Torso_BackLeg" type="revolute">
       <parent link="Torso"/>
       <child  link="BackLeg"/>
       <origin rpy="0 0 0" xyz="0 -10.5 1.4784289620996685" />
     <axis xyz="1 0 0"/>
       <limit effort="0.0" lower="-3.14159" upper="3.14159" velocity="0.0"/>
    </joint>
    <link name="BackLeg">
        <inertial>
            <origin xyz="0 -0.3937623493495004 0" rpy="0 0 0"/>
            <mass value="1" />
            <inertia ixx="100" ixy="0" ixz="0" iyy="100" iyz="0" izz="100" />
        </inertial>
        <visual>
            <origin xyz="0 -0.3937623493495004 0" rpy="0 0 0"/>
            <geometry>
                <box size="0.2 0.7875246986990008 0.2" />
            </geometry>
            <material name="Cyan">
                <color rgba="0 1.0 1.0 1.0"/>
            </material>
        </visual>
        <collision>
            <origin xyz="0 -0.3937623493495004 0" rpy="0 0 0"/>
            <geometry>
                <box size="0.2 0.7875246986990008 0.2" />
            </geometry>
        </collision>
    </link>
    <joint name="Torso_FrontLeg" type="revolute">
       <parent link="Torso"/>
       <child  link="FrontLeg"/>
       <origin rpy="0 0 0" xyz="0 -9.5 1.4784289620996685" />
     <axis xyz="1 0 0"/>
       <limit effort="0.0" lower="-3.14159" upper="3.14159" velocity="0.0"/>
    </joint>
    <link name="FrontLeg">
        <inertial>
            <origin xyz="0 0.5679822023231761 0" rpy="0 0 0"/>
            <mass value="1" />
            <inertia ixx="100" ixy="0" ixz="0" iyy="100" iyz="0" izz="100" />
        </inertial>
        <visual>
            <origin xyz="0 0.5679822023231761 0" rpy="0 0 0"/>
            <geometry>
                <box size="0.2 1.1359644046463522 0.2" />
            </geometry>
            <material name="Cyan">
                <color rgba="0 1.0 1.0 1.0"/>
            </material>
        </visual>
        <collision>
            <origin xyz="0 0.5679822023231761 0" rpy="0 0 0"/>
            <geometry>
                <box size="0.2 1.1359644046463522 0.2" />
            </geometry>
        </collision>
    </link>
    <joint name="Torso_LeftLeg" type="revolute">
       <parent link="Torso"/>
       <child  link="LeftLeg"/>
       <origin rpy="0 0 0" xyz="-0.5 -10 1.4784289620996685" />
     <axis xyz="0 1 0"/>
       <limit effort="0.0" lower="-3.14159" upper="3.14159" velocity="0.0"/>
    </joint>
    <link name="LeftLeg">
        <inertial>
            <origin xyz="-0.7351828939188154 0 0" rpy="0 0 0"/>
            <mass value="1" />
            <inertia ixx="100" ixy="0" ixz="0" iyy="100" iyz="0" izz="100" />
        </inertial>
        <visual>
            <origin xyz="-0.7351828939188154 0 0" rpy="0 0 0"/>
            <geometry>
                <box size="1.4703657878376308 0.2 0.2" />
            </geometry>
            <material name="Cyan">
                <color rgba="0 1.0 1.0 1.0"/>
            </material>
        </visual>
        <collision>
            <origin xyz="-0.7351828939188154 0 0" rpy="0 0 0"/>
            <geometry>
                <box size="1.4703657878376308 0.2 0.2" />
            </geometry>
        </collision>
    </link>
    <joint name="Torso_RightLeg" type="revolute">
       <parent link="Torso"/>
       <child  link="RightLeg"/>
       <origin rpy="0 0 0" xyz="0.5 -10 1.4784289620996685" />
     <axis xyz="0 1 0"/>
       <limit effort="0.0" lower="-3.14159" upper="3.14159" velocity="0.0"/>
    </joint>
    <link name="RightLeg">
        <inertial>
            <origin xyz="0.2834883029992161 0 0" rpy="0 0 0"/>
            <mass value="1" />
            <inertia ixx="100" ixy="0" ixz="0" iyy="100" iyz="0" izz="100" />
        </inertial>
        <visual>
            <origin xyz="0.2834883029992161 0 0" rpy="0 0 0"/>
            <geometry>
                <box size="0.5669766059984322 0.2 0.2" />
            </geometry>
            <material name="Cyan">
                <color rgba="0 1.0 1.0 1.0"/>
            </material>
        </visual>
        <collision>
            <origin xyz="0.2834883029992161 0 0" rpy="0 0 0"/>
            <geometry>
                <box size="0.5669766059984322 0.2 0.2" />
            </geometry>
        </collision>
    </link>
    <joint name="BackLeg_BackLowerLeg" type="revolute">
       <parent link="BackLeg"/>
       <child  link="BackLowerLeg"/>
       <origin rpy="0 0 0" xyz="0 -0.7875246986990008 0" />
     <axis xyz="1 0 0"/>
       <limit effort="0.0" lower="-3.14159" upper="3.14159" velocity="0.0"/>
    </joint>
    <link name="BackLowerLeg">
        <inertial>
            <origin xyz="0 0 -0.7119481275252416" rpy="0 0 0"/>
            <mass value="1" />
            <inertia ixx="100" ixy="0" ixz="0" iyy="100" iyz="0" izz="100" />
        </inertial>
        <visual>
            <origin xyz="0 0 -0.7119481275252416" rpy="0 0 0"/>
            <geometry>
                <box size="0.2 0.2 1.4238962550504832" />
            </geometry>
            <material name="Cyan">
                <color rgba="0 1.0 1.0 1.0"/>
            </material>
        </visual>
        <collision>
            <origin xyz="0 0 -0.7119481275252416" rpy="0 0 0"/>
            <geometry>
                <box size="0.2 0.2 1.4238962550504832" />
            </geometry>
        </collision>
    </link>
    <joint name="FrontLeg_FrontLowerLeg" type="revolute">
       <parent link="FrontLeg"/>
       <child  link="FrontLowerLeg"/>
       <origin rpy="0 0 0" xyz="0 1.1359644046463522 0" />
     <axis xyz="1 0 0"/>
       <limit effort="0.0" lower="-3.14159" upper="3.14159" velocity="0.0"/>
    </joint>
    <link name="FrontLowerLeg">
        <inertial>
            <origin xyz="0 0 -0.5069431968475919" rpy="0 0 0"/>
            <mass value="1" />
            <inertia ixx="100" ixy="0" ixz="0" iyy="100" iyz="0" izz="100" />
        </inertial>
        <visual>
            <origin xyz="0 0 -0.5069431968475919" rpy="0 0 0"/>
            <geometry>
                <box size="0.2 0.2 1.0138863936951839" />
            </geometry>
            <material name="Cyan">
                <color rgba="0 1.0 1.0 1.0"/>
            </material>
        </visual>
        <collision>
            <origin xyz="0 0 -0.5069431968475919" rpy="0 0 0"/>
            <geometry>
                <box size="0.2 0.2 1.0138863936951839" />
            </geometry>
        </collision>
    </link>
    <joint name="LeftLeg_LeftLowerLeg" type="revolute">
       <parent link="LeftLeg"/>
       <child  link="LeftLowerLeg"/>
       <origin rpy="0 0 0" xyz="-1.4703657878376308 0 0" />
     <axis xyz="0 1 0"/>
       <limit effort="0.0" lower="-3.14159" upper="3.14159" velocity="0.0"/>
    </joint>
    <link name="LeftLowerLeg">
        <inertial>
            <origin xyz="0 0 -0.6646552981476088" rpy="0 0 0"/>
            <mass value="1" />
            <inertia ixx="100" ixy="0" ixz="0" iyy="100" iyz="0" izz="100" />
        </inertial>
        <visual>
            <origin xyz="0 0 -0.6646552981476088" rpy="0 0 0"/>
            <geometry>
                <box size="0.2 0.2 1.3293105962952176" />
            </geometry>
            <material name="Cyan">
                <color rgba="0 1.0 1.0 1.0"/>
            </material>
        </visual>
        <collision>
            <origin xyz="0 0 -0.6646552981476088" rpy="0 0 0"/>
            <geometry>
                <box size="0.2 0.2 1.3293105962952176" />
            </geometry>
        </collision>
    </link>
    <joint name="RightLeg_RightLowerLeg" type="revolute">
       <parent link="RightLeg"/>
       <child  link="RightLowerLeg"/>
       <origin rpy="0 0 0" xyz="0.5669766059984322 0 0" />
     <axis xyz="0 1 0"/>
       <limit effort="0.0" lower="-3.14159" upper="3.14159" velocity="0.0"/>
    </joint>
    <link name="RightLowerLeg">
        <inertial>
            <origin xyz="0 0 -0.7392144810498342" rpy="0 0 0"/>
            <mass value="1" />
            <inertia ixx="100" ixy="0" ixz="0" iyy="100" iyz="0" izz="100" />
        </inertial>
        <visual>
            <origin xyz="0 0 -0.7392144810498342" rpy="0 0 0"/>
            <geometry>
                <box size="0.2 0.2 1.4784289620996685" />
            </geometry>
            <material name="Cyan">
                <color rgba="0 1.0 1.0 1.0"/>
            </material>
        </visual>
        <collision>
            <origin xyz="0 0 -0.7392144810498342" rpy="0 0 0"/>
            <geometry>
                <box size="0.2 0.2 1.4784289620996685" />
            </geometry>
        </collision>
    </link>
</robot>