<robot name = "robot">
    <link name="Torso">
        <inertial>
            <origin xyz="0 -10 1.4928162660686628" rpy="0 0 0"/>
            <mass value="1" />
            <inertia ixx="100" ixy="0" ixz="0" iyy="100" iyz="0" izz="100" />
        </inertial>
        <visual>
            <origin xyz="0 -10 1.4928162660686628" rpy="0 0 0"/>
            <geometry>
                <box size="1 1 1" />
            </geometry>
            <material name="Cyan">
                <color rgba="0 1.0 1.0 1.0"/>
            </material>
        </visual>
        <collision>
            <origin xyz="0 -10 1.4928162660686628" rpy="0 0 0"/>
            <geometry>
                <box size="1 1 1" />
            </geometry>
        </collision>
    </link>
    <joint name="Torso_BackLeg" type="revolute">
       <parent link="Torso"/>
       <child  link="BackLeg"/>
       <origin rpy="0 0 0" xyz="0 -10.5 1.4928162660686628" />
     <axis xyz="1 0 0"/>
       <limit effort="0.0" lower="-3.14159" upper="3.14159" velocity="0.0"/>
    </joint>
    <link name="BackLeg">
        <inertial>
            <origin xyz="0 -0.4107070409384773 0" rpy="0 0 0"/>
            <mass value="1" />
            <inertia ixx="100" ixy="0" ixz="0" iyy="100" iyz="0" izz="100" />
        </inertial>
        <visual>
            <origin xyz="0 -0.4107070409384773 0" rpy="0 0 0"/>
            <geometry>
                <box size="0.2 0.8214140818769546 0.2" />
            </geometry>
            <material name="Cyan">
                <color rgba="0 1.0 1.0 1.0"/>
            </material>
        </visual>
        <collision>
            <origin xyz="0 -0.4107070409384773 0" rpy="0 0 0"/>
            <geometry>
                <box size="0.2 0.8214140818769546 0.2" />
            </geometry>
        </collision>
    </link>
    <joint name="Torso_FrontLeg" type="revolute">
       <parent link="Torso"/>
       <child  link="FrontLeg"/>
       <origin rpy="0 0 0" xyz="0 -9.5 1.4928162660686628" />
     <axis xyz="1 0 0"/>
       <limit effort="0.0" lower="-3.14159" upper="3.14159" velocity="0.0"/>
    </joint>
    <link name="FrontLeg">
        <inertial>
            <origin xyz="0 0.5616266620335983 0" rpy="0 0 0"/>
            <mass value="1" />
            <inertia ixx="100" ixy="0" ixz="0" iyy="100" iyz="0" izz="100" />
        </inertial>
        <visual>
            <origin xyz="0 0.5616266620335983 0" rpy="0 0 0"/>
            <geometry>
                <box size="0.2 1.1232533240671967 0.2" />
            </geometry>
            <material name="Cyan">
                <color rgba="0 1.0 1.0 1.0"/>
            </material>
        </visual>
        <collision>
            <origin xyz="0 0.5616266620335983 0" rpy="0 0 0"/>
            <geometry>
                <box size="0.2 1.1232533240671967 0.2" />
            </geometry>
        </collision>
    </link>
    <joint name="Torso_LeftLeg" type="revolute">
       <parent link="Torso"/>
       <child  link="LeftLeg"/>
       <origin rpy="0 0 0" xyz="-0.5 -10 1.4928162660686628" />
     <axis xyz="0 1 0"/>
       <limit effort="0.0" lower="-3.14159" upper="3.14159" velocity="0.0"/>
    </joint>
    <link name="LeftLeg">
        <inertial>
            <origin xyz="-0.7464081330343314 0 0" rpy="0 0 0"/>
            <mass value="1" />
            <inertia ixx="100" ixy="0" ixz="0" iyy="100" iyz="0" izz="100" />
        </inertial>
        <visual>
            <origin xyz="-0.7464081330343314 0 0" rpy="0 0 0"/>
            <geometry>
                <box size="1.4928162660686628 0.2 0.2" />
            </geometry>
            <material name="Cyan">
                <color rgba="0 1.0 1.0 1.0"/>
            </material>
        </visual>
        <collision>
            <origin xyz="-0.7464081330343314 0 0" rpy="0 0 0"/>
            <geometry>
                <box size="1.4928162660686628 0.2 0.2" />
            </geometry>
        </collision>
    </link>
    <joint name="Torso_RightLeg" type="revolute">
       <parent link="Torso"/>
       <child  link="RightLeg"/>
       <origin rpy="0 0 0" xyz="0.5 -10 1.4928162660686628" />
     <axis xyz="0 1 0"/>
       <limit effort="0.0" lower="-3.14159" upper="3.14159" velocity="0.0"/>
    </joint>
    <link name="RightLeg">
        <inertial>
            <origin xyz="0.48227554650728544 0 0" rpy="0 0 0"/>
            <mass value="1" />
            <inertia ixx="100" ixy="0" ixz="0" iyy="100" iyz="0" izz="100" />
        </inertial>
        <visual>
            <origin xyz="0.48227554650728544 0 0" rpy="0 0 0"/>
            <geometry>
                <box size="0.9645510930145709 0.2 0.2" />
            </geometry>
            <material name="Cyan">
                <color rgba="0 1.0 1.0 1.0"/>
            </material>
        </visual>
        <collision>
            <origin xyz="0.48227554650728544 0 0" rpy="0 0 0"/>
            <geometry>
                <box size="0.9645510930145709 0.2 0.2" />
            </geometry>
        </collision>
    </link>
    <joint name="BackLeg_BackLowerLeg" type="revolute">
       <parent link="BackLeg"/>
       <child  link="BackLowerLeg"/>
       <origin rpy="0 0 0" xyz="0 -0.8214140818769546 0" />
     <axis xyz="1 0 0"/>
       <limit effort="0.0" lower="-3.14159" upper="3.14159" velocity="0.0"/>
    </joint>
    <link name="BackLowerLeg">
        <inertial>
            <origin xyz="0 0 -0.4374894530413221" rpy="0 0 0"/>
            <mass value="1" />
            <inertia ixx="100" ixy="0" ixz="0" iyy="100" iyz="0" izz="100" />
        </inertial>
        <visual>
            <origin xyz="0 0 -0.4374894530413221" rpy="0 0 0"/>
            <geometry>
                <box size="0.2 0.2 0.8749789060826442" />
            </geometry>
            <material name="Cyan">
                <color rgba="0 1.0 1.0 1.0"/>
            </material>
        </visual>
        <collision>
            <origin xyz="0 0 -0.4374894530413221" rpy="0 0 0"/>
            <geometry>
                <box size="0.2 0.2 0.8749789060826442" />
            </geometry>
        </collision>
    </link>
    <joint name="FrontLeg_FrontLowerLeg" type="revolute">
       <parent link="FrontLeg"/>
       <child  link="FrontLowerLeg"/>
       <origin rpy="0 0 0" xyz="0 1.1232533240671967 0" />
     <axis xyz="1 0 0"/>
       <limit effort="0.0" lower="-3.14159" upper="3.14159" velocity="0.0"/>
    </joint>
    <link name="FrontLowerLeg">
        <inertial>
            <origin xyz="0 0 -0.6396139836514009" rpy="0 0 0"/>
            <mass value="1" />
            <inertia ixx="100" ixy="0" ixz="0" iyy="100" iyz="0" izz="100" />
        </inertial>
        <visual>
            <origin xyz="0 0 -0.6396139836514009" rpy="0 0 0"/>
            <geometry>
                <box size="0.2 0.2 1.2792279673028017" />
            </geometry>
            <material name="Cyan">
                <color rgba="0 1.0 1.0 1.0"/>
            </material>
        </visual>
        <collision>
            <origin xyz="0 0 -0.6396139836514009" rpy="0 0 0"/>
            <geometry>
                <box size="0.2 0.2 1.2792279673028017" />
            </geometry>
        </collision>
    </link>
    <joint name="LeftLeg_LeftLowerLeg" type="revolute">
       <parent link="LeftLeg"/>
       <child  link="LeftLowerLeg"/>
       <origin rpy="0 0 0" xyz="-1.4928162660686628 0 0" />
     <axis xyz="0 1 0"/>
       <limit effort="0.0" lower="-3.14159" upper="3.14159" velocity="0.0"/>
    </joint>
    <link name="LeftLowerLeg">
        <inertial>
            <origin xyz="0 0 -0.272756678879159" rpy="0 0 0"/>
            <mass value="1" />
            <inertia ixx="100" ixy="0" ixz="0" iyy="100" iyz="0" izz="100" />
        </inertial>
        <visual>
            <origin xyz="0 0 -0.272756678879159" rpy="0 0 0"/>
            <geometry>
                <box size="0.2 0.2 0.545513357758318" />
            </geometry>
            <material name="Cyan">
                <color rgba="0 1.0 1.0 1.0"/>
            </material>
        </visual>
        <collision>
            <origin xyz="0 0 -0.272756678879159" rpy="0 0 0"/>
            <geometry>
                <box size="0.2 0.2 0.545513357758318" />
            </geometry>
        </collision>
    </link>
    <joint name="RightLeg_RightLowerLeg" type="revolute">
       <parent link="RightLeg"/>
       <child  link="RightLowerLeg"/>
       <origin rpy="0 0 0" xyz="0.9645510930145709 0 0" />
     <axis xyz="0 1 0"/>
       <limit effort="0.0" lower="-3.14159" upper="3.14159" velocity="0.0"/>
    </joint>
    <link name="RightLowerLeg">
        <inertial>
            <origin xyz="0 0 -0.7316258299718714" rpy="0 0 0"/>
            <mass value="1" />
            <inertia ixx="100" ixy="0" ixz="0" iyy="100" iyz="0" izz="100" />
        </inertial>
        <visual>
            <origin xyz="0 0 -0.7316258299718714" rpy="0 0 0"/>
            <geometry>
                <box size="0.2 0.2 1.4632516599437428" />
            </geometry>
            <material name="Cyan">
                <color rgba="0 1.0 1.0 1.0"/>
            </material>
        </visual>
        <collision>
            <origin xyz="0 0 -0.7316258299718714" rpy="0 0 0"/>
            <geometry>
                <box size="0.2 0.2 1.4632516599437428" />
            </geometry>
        </collision>
    </link>
</robot>